import { render, screen, fireEvent } from '@testing-library/react';
import ErrorBoundary from '../ErrorBoundary';

const ThrowError = () => {
  throw new Error('Test error');
};

describe('ErrorBoundary', () => {
  beforeEach(() => {
    vi.spyOn(console, 'error').mockImplementation(() => {});
  });

  afterEach(() => {
    vi.restoreAllMocks();
  });

  it('renders children when there is no error', () => {
    render(
      <ErrorBoundary>
        <div>Test content</div>
      </ErrorBoundary>
    );
    expect(screen.getByText('Test content')).toBeInTheDocument();
  });

  it('renders error UI when there is an error', () => {
    render(
      <ErrorBoundary>
        <ThrowError />
      </ErrorBoundary>
    );
    expect(screen.getByText(/something went wrong/i)).toBeInTheDocument();
    expect(screen.getByText(/test error/i)).toBeInTheDocument();
  });

  it('allows retry when error occurs', () => {
    const { rerender } = render(
      <ErrorBoundary>
        <ThrowError />
      </ErrorBoundary>
    );
    
    const retryButton = screen.getByText(/try again/i);
    expect(retryButton).toBeInTheDocument();
    
    // Mock window.location.reload
    const reloadMock = vi.fn();
    Object.defineProperty(window, 'location', {
      value: { reload: reloadMock },
      writable: true,
    });
    
    fireEvent.click(retryButton);
    expect(reloadMock).toHaveBeenCalled();
  });
});